I'm sorry, but an uncaught exception occurred.

While running game code:
  File "game/script.rpy", line 263, in script
    Miyu "(Miyu: Are you ready for this?)"
Exception: Sayer 'Miyu' is not defined.

-- Full Traceback ------------------------------------------------------------

Full traceback:
  File "game/script.rpy", line 263, in script
    Miyu "(Miyu: Are you ready for this?)"
  File "C:\Users\jhunm\Documents\renpy-8.3.4-sdk\renpy\ast.py", line 2579, in execute
    Say.execute(self)
  File "C:\Users\jhunm\Documents\renpy-8.3.4-sdk\renpy\ast.py", line 581, in execute
    who = eval_who(self.who, self.who_fast)
  File "C:\Users\jhunm\Documents\renpy-8.3.4-sdk\renpy\ast.py", line 470, in eval_who
    raise Exception("Sayer '%s' is not defined." % who)
Exception: Sayer 'Miyu' is not defined.

Windows-10-10.0.22000 AMD64
Ren'Py 8.3.4.24120703
LostInTheAbyss 1.0
Tue Dec 10 02:30:09 2024
